08-10-2022 12:23:07 PM Error in Get Read Proper Data Function!!!
Traceback (most recent call last):
  File "G:\AdventsProduct\Others\Medical Insurance\func.py", line 69, in get_read_proper_data
    data = pd.read_excel(file_location)
  File "C:\Users\user\Envs\django\lib\site-packages\pandas\util\_decorators.py", line 299, in wrapper
    return func(*args, **kwargs)
  File "C:\Users\user\Envs\django\lib\site-packages\pandas\io\excel\_base.py", line 336, in read_excel
    io = ExcelFile(io, storage_options=storage_options, engine=engine)
  File "C:\Users\user\Envs\django\lib\site-packages\pandas\io\excel\_base.py", line 1071, in __init__
    ext = inspect_excel_format(
  File "C:\Users\user\Envs\django\lib\site-packages\pandas\io\excel\_base.py", line 947, in inspect_excel_format
    assert content_or_path is not None
AssertionError
08-10-2022 12:23:07 PM Error in Get Filter Insurance Company Function!!!
Traceback (most recent call last):
  File "G:\AdventsProduct\Others\Medical Insurance\merge_data.py", line 47, in get_filter_insurance_company
    data_insurance_company = associate_merged_sales_merged_mis_data[associate_merged_sales_merged_mis_data['Insurance Company'] == insurance_company_name]
TypeError: string indices must be integers
08-10-2022 02:13:06 PM Error in Add Column with Date Val Function!!!
Traceback (most recent call last):
  File "C:\Users\user\Envs\django\lib\site-packages\pandas\core\indexes\base.py", line 3080, in get_loc
    return self._engine.get_loc(casted_key)
  File "pandas\_libs\index.pyx", line 70, in pandas._libs.index.IndexEngine.get_loc
  File "pandas\_libs\index.pyx", line 101, in pandas._libs.index.IndexEngine.get_loc
  File "pandas\_libs\hashtable_class_helper.pxi", line 4554, in pandas._libs.hashtable.PyObjectHashTable.get_item
  File "pandas\_libs\hashtable_class_helper.pxi", line 4562, in pandas._libs.hashtable.PyObjectHashTable.get_item
KeyError: 'exit_actual_dol'

The above exception was the direct cause of the following exception:

Traceback (most recent call last):
  File "G:\AdventsProduct\Others\Medical Insurance\func.py", line 126, in add_column_with_date_val
    data_frame[new_column_name] = data_frame[column].apply(
  File "C:\Users\user\Envs\django\lib\site-packages\pandas\core\frame.py", line 3024, in __getitem__
    indexer = self.columns.get_loc(key)
  File "C:\Users\user\Envs\django\lib\site-packages\pandas\core\indexes\base.py", line 3082, in get_loc
    raise KeyError(key) from err
KeyError: 'exit_actual_dol'
08-10-2022 02:13:07 PM Error in Get Write File Function!!!
Traceback (most recent call last):
  File "G:\AdventsProduct\Others\Medical Insurance\func.py", line 102, in get_write_file
    data_frame.to_excel(write_path, index=False)
AttributeError: 'NoneType' object has no attribute 'to_excel'
08-10-2022 05:50:38 PM Error in Medical Insurance Deletion Function!!!
Traceback (most recent call last):
  File "G:\AdventsProduct\Others\Medical Insurance\process.py", line 85, in medical_insurance_deletion
    data_deletion = classification.deletion(data_frame=data, inception_data_frame=inception_data)
TypeError: deletion() missing 2 required positional arguments: 'upload_month' and 'upload_year'
08-10-2022 05:50:38 PM Error in Get Read Proper Data Function!!!
Traceback (most recent call last):
  File "G:\AdventsProduct\Others\Medical Insurance\func.py", line 69, in get_read_proper_data
    data = pd.read_excel(file_location)
  File "C:\Users\user\Envs\django\lib\site-packages\pandas\util\_decorators.py", line 299, in wrapper
    return func(*args, **kwargs)
  File "C:\Users\user\Envs\django\lib\site-packages\pandas\io\excel\_base.py", line 336, in read_excel
    io = ExcelFile(io, storage_options=storage_options, engine=engine)
  File "C:\Users\user\Envs\django\lib\site-packages\pandas\io\excel\_base.py", line 1071, in __init__
    ext = inspect_excel_format(
  File "C:\Users\user\Envs\django\lib\site-packages\pandas\io\excel\_base.py", line 949, in inspect_excel_format
    with get_handle(
  File "C:\Users\user\Envs\django\lib\site-packages\pandas\io\common.py", line 651, in get_handle
    handle = open(handle, ioargs.mode)
FileNotFoundError: [Errno 2] No such file or directory: 'H:/Testing/Medical Insurance/A-Testing/Medical Insurance/august-2022/08102022/med_ins_aug_22_data_deletion.xlsx'
08-10-2022 05:51:34 PM Error in Addition and Deletion Function!!!
Traceback (most recent call last):
  File "G:\AdventsProduct\Others\Medical Insurance\classifications.py", line 201, in addition_and_deletion
    data_frame['classification_1'] = data_frame.apply(
AttributeError: 'str' object has no attribute 'apply'
08-10-2022 05:51:34 PM Error in Get Write File Function!!!
Traceback (most recent call last):
  File "G:\AdventsProduct\Others\Medical Insurance\func.py", line 102, in get_write_file
    data_frame.to_excel(write_path, index=False)
AttributeError: 'str' object has no attribute 'to_excel'
08-10-2022 05:51:34 PM Error in Get Read Proper Data Function!!!
Traceback (most recent call last):
  File "G:\AdventsProduct\Others\Medical Insurance\func.py", line 69, in get_read_proper_data
    data = pd.read_excel(file_location)
  File "C:\Users\user\Envs\django\lib\site-packages\pandas\util\_decorators.py", line 299, in wrapper
    return func(*args, **kwargs)
  File "C:\Users\user\Envs\django\lib\site-packages\pandas\io\excel\_base.py", line 336, in read_excel
    io = ExcelFile(io, storage_options=storage_options, engine=engine)
  File "C:\Users\user\Envs\django\lib\site-packages\pandas\io\excel\_base.py", line 1071, in __init__
    ext = inspect_excel_format(
  File "C:\Users\user\Envs\django\lib\site-packages\pandas\io\excel\_base.py", line 949, in inspect_excel_format
    with get_handle(
  File "C:\Users\user\Envs\django\lib\site-packages\pandas\io\common.py", line 651, in get_handle
    handle = open(handle, ioargs.mode)
FileNotFoundError: [Errno 2] No such file or directory: 'H:/Testing/Medical Insurance/A-Testing/Medical Insurance/august-2022/08102022/med_ins_aug_22_data_addition_and_deletion.xlsx'
08-10-2022 05:52:31 PM Error in Already Deletion Function!!!
Traceback (most recent call last):
  File "G:\AdventsProduct\Others\Medical Insurance\classifications.py", line 243, in already_deletion
    data_frame['classification_1'] = data_frame.apply(
AttributeError: 'str' object has no attribute 'apply'
08-10-2022 05:52:31 PM Error in Get Write File Function!!!
Traceback (most recent call last):
  File "G:\AdventsProduct\Others\Medical Insurance\func.py", line 102, in get_write_file
    data_frame.to_excel(write_path, index=False)
AttributeError: 'str' object has no attribute 'to_excel'
08-10-2022 05:52:31 PM Error in Get Read Proper Data Function!!!
Traceback (most recent call last):
  File "G:\AdventsProduct\Others\Medical Insurance\func.py", line 69, in get_read_proper_data
    data = pd.read_excel(file_location)
  File "C:\Users\user\Envs\django\lib\site-packages\pandas\util\_decorators.py", line 299, in wrapper
    return func(*args, **kwargs)
  File "C:\Users\user\Envs\django\lib\site-packages\pandas\io\excel\_base.py", line 336, in read_excel
    io = ExcelFile(io, storage_options=storage_options, engine=engine)
  File "C:\Users\user\Envs\django\lib\site-packages\pandas\io\excel\_base.py", line 1071, in __init__
    ext = inspect_excel_format(
  File "C:\Users\user\Envs\django\lib\site-packages\pandas\io\excel\_base.py", line 949, in inspect_excel_format
    with get_handle(
  File "C:\Users\user\Envs\django\lib\site-packages\pandas\io\common.py", line 651, in get_handle
    handle = open(handle, ioargs.mode)
FileNotFoundError: [Errno 2] No such file or directory: 'H:/Testing/Medical Insurance/A-Testing/Medical Insurance/august-2022/08102022/med_ins_aug_22_data_already_deletion.xlsx'
08-10-2022 05:53:19 PM Error in Addition Function!!!
Traceback (most recent call last):
  File "G:\AdventsProduct\Others\Medical Insurance\classifications.py", line 271, in additions
    data_frame['classification_1'] = data_frame.apply(
AttributeError: 'str' object has no attribute 'apply'
08-10-2022 05:53:19 PM Error in Get Write File Function!!!
Traceback (most recent call last):
  File "G:\AdventsProduct\Others\Medical Insurance\func.py", line 102, in get_write_file
    data_frame.to_excel(write_path, index=False)
AttributeError: 'str' object has no attribute 'to_excel'
08-10-2022 05:53:19 PM Error in Get Read Proper Data Function!!!
Traceback (most recent call last):
  File "G:\AdventsProduct\Others\Medical Insurance\func.py", line 69, in get_read_proper_data
    data = pd.read_excel(file_location)
  File "C:\Users\user\Envs\django\lib\site-packages\pandas\util\_decorators.py", line 299, in wrapper
    return func(*args, **kwargs)
  File "C:\Users\user\Envs\django\lib\site-packages\pandas\io\excel\_base.py", line 336, in read_excel
    io = ExcelFile(io, storage_options=storage_options, engine=engine)
  File "C:\Users\user\Envs\django\lib\site-packages\pandas\io\excel\_base.py", line 1071, in __init__
    ext = inspect_excel_format(
  File "C:\Users\user\Envs\django\lib\site-packages\pandas\io\excel\_base.py", line 949, in inspect_excel_format
    with get_handle(
  File "C:\Users\user\Envs\django\lib\site-packages\pandas\io\common.py", line 651, in get_handle
    handle = open(handle, ioargs.mode)
FileNotFoundError: [Errno 2] No such file or directory: 'H:/Testing/Medical Insurance/A-Testing/Medical Insurance/august-2022/08102022/med_ins_aug_22_data_addition.xlsx'
08-10-2022 05:54:15 PM Error in Reactivation Function!!!
Traceback (most recent call last):
  File "G:\AdventsProduct\Others\Medical Insurance\classifications.py", line 310, in reactivation
    data_frame['classification_1'] = data_frame.apply(
AttributeError: 'str' object has no attribute 'apply'
08-10-2022 05:54:15 PM Error in Get Write File Function!!!
Traceback (most recent call last):
  File "G:\AdventsProduct\Others\Medical Insurance\func.py", line 102, in get_write_file
    data_frame.to_excel(write_path, index=False)
AttributeError: 'str' object has no attribute 'to_excel'
08-10-2022 05:54:15 PM Error in Get Read Proper Data Function!!!
Traceback (most recent call last):
  File "G:\AdventsProduct\Others\Medical Insurance\func.py", line 69, in get_read_proper_data
    data = pd.read_excel(file_location)
  File "C:\Users\user\Envs\django\lib\site-packages\pandas\util\_decorators.py", line 299, in wrapper
    return func(*args, **kwargs)
  File "C:\Users\user\Envs\django\lib\site-packages\pandas\io\excel\_base.py", line 336, in read_excel
    io = ExcelFile(io, storage_options=storage_options, engine=engine)
  File "C:\Users\user\Envs\django\lib\site-packages\pandas\io\excel\_base.py", line 1071, in __init__
    ext = inspect_excel_format(
  File "C:\Users\user\Envs\django\lib\site-packages\pandas\io\excel\_base.py", line 949, in inspect_excel_format
    with get_handle(
  File "C:\Users\user\Envs\django\lib\site-packages\pandas\io\common.py", line 651, in get_handle
    handle = open(handle, ioargs.mode)
FileNotFoundError: [Errno 2] No such file or directory: 'H:/Testing/Medical Insurance/A-Testing/Medical Insurance/august-2022/08102022/med_ins_aug_22_data_reactivation.xlsx'
08-10-2022 05:54:15 PM Error in Next Month Addition Function!!!
Traceback (most recent call last):
  File "G:\AdventsProduct\Others\Medical Insurance\classifications.py", line 339, in next_month_addition
    data_frame['classification_1'] = data_frame.apply(
AttributeError: 'str' object has no attribute 'apply'
08-10-2022 05:54:15 PM Error in Get Write File Function!!!
Traceback (most recent call last):
  File "G:\AdventsProduct\Others\Medical Insurance\func.py", line 102, in get_write_file
    data_frame.to_excel(write_path, index=False)
AttributeError: 'str' object has no attribute 'to_excel'
08-10-2022 05:54:15 PM Error in Get Read Proper Data Function!!!
Traceback (most recent call last):
  File "G:\AdventsProduct\Others\Medical Insurance\func.py", line 69, in get_read_proper_data
    data = pd.read_excel(file_location)
  File "C:\Users\user\Envs\django\lib\site-packages\pandas\util\_decorators.py", line 299, in wrapper
    return func(*args, **kwargs)
  File "C:\Users\user\Envs\django\lib\site-packages\pandas\io\excel\_base.py", line 336, in read_excel
    io = ExcelFile(io, storage_options=storage_options, engine=engine)
  File "C:\Users\user\Envs\django\lib\site-packages\pandas\io\excel\_base.py", line 1071, in __init__
    ext = inspect_excel_format(
  File "C:\Users\user\Envs\django\lib\site-packages\pandas\io\excel\_base.py", line 949, in inspect_excel_format
    with get_handle(
  File "C:\Users\user\Envs\django\lib\site-packages\pandas\io\common.py", line 651, in get_handle
    handle = open(handle, ioargs.mode)
FileNotFoundError: [Errno 2] No such file or directory: 'H:/Testing/Medical Insurance/A-Testing/Medical Insurance/august-2022/08102022/med_ins_aug_22_data_next_month_addition.xlsx'
08-10-2022 05:55:12 PM Error in Next Month Deletion Function!!!
Traceback (most recent call last):
  File "G:\AdventsProduct\Others\Medical Insurance\classifications.py", line 380, in next_month_deletion
    data_frame['classification_1'] = data_frame.apply(
AttributeError: 'str' object has no attribute 'apply'
08-10-2022 05:55:12 PM Error in Get Write File Function!!!
Traceback (most recent call last):
  File "G:\AdventsProduct\Others\Medical Insurance\func.py", line 102, in get_write_file
    data_frame.to_excel(write_path, index=False)
AttributeError: 'str' object has no attribute 'to_excel'
10-10-2022 08:55:27 AM Error in Get Read Proper Data Function!!!
Traceback (most recent call last):
  File "G:\AdventsProduct\Others\Medical Insurance\func.py", line 69, in get_read_proper_data
    data = pd.read_excel(file_location)
  File "C:\Users\user\Envs\django\lib\site-packages\pandas\util\_decorators.py", line 299, in wrapper
    return func(*args, **kwargs)
  File "C:\Users\user\Envs\django\lib\site-packages\pandas\io\excel\_base.py", line 336, in read_excel
    io = ExcelFile(io, storage_options=storage_options, engine=engine)
  File "C:\Users\user\Envs\django\lib\site-packages\pandas\io\excel\_base.py", line 1071, in __init__
    ext = inspect_excel_format(
  File "C:\Users\user\Envs\django\lib\site-packages\pandas\io\excel\_base.py", line 949, in inspect_excel_format
    with get_handle(
  File "C:\Users\user\Envs\django\lib\site-packages\pandas\io\common.py", line 651, in get_handle
    handle = open(handle, ioargs.mode)
FileNotFoundError: [Errno 2] No such file or directory: 'H:/Testing/Medical Insurance/A-Testing/Medical Insurance/august-2022/08102022/med_ins_aug_22_data_ptp.xlsx'
18-10-2022 10:37:51 AM Error in Reading Data in get data from file!!!
Traceback (most recent call last):
  File "G:\AdventsProduct\Others\Medical Insurance\Packages\read_file.py", line 227, in get_data_from_file
    data = pd.read_excel(file_path, skiprows=int(column_start_row) - 1, usecols=attribute_list, engine="pyxlsb", converters=data_column_converter, sheet_name=sheet_name)[attribute_list]
  File "C:\Users\user\Envs\django\lib\site-packages\pandas\util\_decorators.py", line 299, in wrapper
    return func(*args, **kwargs)
  File "C:\Users\user\Envs\django\lib\site-packages\pandas\io\excel\_base.py", line 344, in read_excel
    data = io.parse(
  File "C:\Users\user\Envs\django\lib\site-packages\pandas\io\excel\_base.py", line 1170, in parse
    return self._reader.parse(
  File "C:\Users\user\Envs\django\lib\site-packages\pandas\io\excel\_base.py", line 488, in parse
    sheet = self.get_sheet_by_name(asheetname)
  File "C:\Users\user\Envs\django\lib\site-packages\pandas\io\excel\_pyxlsb.py", line 50, in get_sheet_by_name
    self.raise_if_bad_sheet_by_name(name)
  File "C:\Users\user\Envs\django\lib\site-packages\pandas\io\excel\_base.py", line 437, in raise_if_bad_sheet_by_name
    raise ValueError(f"Worksheet named '{name}' not found")
ValueError: Worksheet named 'STAFFING SR AUG22' not found
18-10-2022 10:37:51 AM Error in Get Salary Register Function!!!
Traceback (most recent call last):
  File "G:\AdventsProduct\Others\Medical Insurance\data.py", line 56, in get_salary_register
    salary_register.rename(columns = salary_register_columns_dict, inplace=True)
AttributeError: 'NoneType' object has no attribute 'rename'
18-10-2022 10:55:48 AM Error in Reading Data in get data from file!!!
Traceback (most recent call last):
  File "C:\Users\user\Envs\django\lib\site-packages\pandas\io\parsers.py", line 2789, in _handle_usecols
    col_indices.append(usecols_key.index(col))
ValueError: 'EMPF' is not in list

During handling of the above exception, another exception occurred:

Traceback (most recent call last):
  File "G:\AdventsProduct\Others\Medical Insurance\Packages\read_file.py", line 227, in get_data_from_file
    data = pd.read_excel(file_path, skiprows=int(column_start_row) - 1, usecols=attribute_list, engine="pyxlsb", converters=data_column_converter, sheet_name=sheet_name)[attribute_list]
  File "C:\Users\user\Envs\django\lib\site-packages\pandas\util\_decorators.py", line 299, in wrapper
    return func(*args, **kwargs)
  File "C:\Users\user\Envs\django\lib\site-packages\pandas\io\excel\_base.py", line 344, in read_excel
    data = io.parse(
  File "C:\Users\user\Envs\django\lib\site-packages\pandas\io\excel\_base.py", line 1170, in parse
    return self._reader.parse(
  File "C:\Users\user\Envs\django\lib\site-packages\pandas\io\excel\_base.py", line 543, in parse
    parser = TextParser(
  File "C:\Users\user\Envs\django\lib\site-packages\pandas\io\parsers.py", line 2229, in TextParser
    return TextFileReader(*args, **kwds)
  File "C:\Users\user\Envs\django\lib\site-packages\pandas\io\parsers.py", line 819, in __init__
    self._engine = self._make_engine(self.engine)
  File "C:\Users\user\Envs\django\lib\site-packages\pandas\io\parsers.py", line 1050, in _make_engine
    return mapping[engine](self.f, **self.options)  # type: ignore[call-arg]
  File "C:\Users\user\Envs\django\lib\site-packages\pandas\io\parsers.py", line 2310, in __init__
    ) = self._infer_columns()
  File "C:\Users\user\Envs\django\lib\site-packages\pandas\io\parsers.py", line 2723, in _infer_columns
    columns = self._handle_usecols(columns, columns[0])
  File "C:\Users\user\Envs\django\lib\site-packages\pandas\io\parsers.py", line 2791, in _handle_usecols
    _validate_usecols_names(self.usecols, usecols_key)
  File "C:\Users\user\Envs\django\lib\site-packages\pandas\io\parsers.py", line 1162, in _validate_usecols_names
    raise ValueError(
ValueError: Usecols do not match columns, columns expected but not found: ['EMPF', 'DA', 'EMPCOMP', 'Basic']
18-10-2022 12:01:02 PM Error in Reading Data in get data from file!!!
Traceback (most recent call last):
  File "G:\AdventsProduct\Others\Medical Insurance\Packages\read_file.py", line 227, in get_data_from_file
    data = pd.read_excel(file_path, skiprows=int(column_start_row) - 1, usecols=attribute_list, engine="pyxlsb", converters=data_column_converter, sheet_name=sheet_name)[attribute_list]
  File "C:\Users\user\Envs\django\lib\site-packages\pandas\util\_decorators.py", line 299, in wrapper
    return func(*args, **kwargs)
  File "C:\Users\user\Envs\django\lib\site-packages\pandas\io\excel\_base.py", line 336, in read_excel
    io = ExcelFile(io, storage_options=storage_options, engine=engine)
  File "C:\Users\user\Envs\django\lib\site-packages\pandas\io\excel\_base.py", line 1131, in __init__
    self._reader = self._engines[engine](self._io, storage_options=storage_options)
  File "C:\Users\user\Envs\django\lib\site-packages\pandas\io\excel\_pyxlsb.py", line 28, in __init__
    super().__init__(filepath_or_buffer, storage_options=storage_options)
  File "C:\Users\user\Envs\django\lib\site-packages\pandas\io\excel\_base.py", line 391, in __init__
    self.book = self.load_workbook(self.handles.handle)
  File "C:\Users\user\Envs\django\lib\site-packages\pandas\io\excel\_pyxlsb.py", line 43, in load_workbook
    return open_workbook(filepath_or_buffer)
  File "C:\Users\user\Envs\django\lib\site-packages\pyxlsb\__init__.py", line 11, in open_workbook
    return Workbook(fp=zf, debug=debug)
  File "C:\Users\user\Envs\django\lib\site-packages\pyxlsb\workbook.py", line 20, in __init__
    self._parse()
  File "C:\Users\user\Envs\django\lib\site-packages\pyxlsb\workbook.py", line 34, in _parse
    with self._zf.open('xl/_rels/workbook.bin.rels', 'r') as zf:
  File "c:\users\user\appdata\local\programs\python\python39\lib\zipfile.py", line 1502, in open
    zinfo = self.getinfo(name)
  File "c:\users\user\appdata\local\programs\python\python39\lib\zipfile.py", line 1429, in getinfo
    raise KeyError(
KeyError: "There is no item named 'xl/_rels/workbook.bin.rels' in the archive"
18-10-2022 12:01:03 PM Error in Writing Inception Data!!!
Traceback (most recent call last):
  File "G:\AdventsProduct\Others\Medical Insurance\data.py", line 164, in get_inception_data
    inception_data["Status"] = inception_data.apply(
AttributeError: 'NoneType' object has no attribute 'apply'
27-10-2022 09:17:23 PM Error in Get Write File Function!!!
Traceback (most recent call last):
  File "C:\Users\user\Envs\django\lib\site-packages\pandas\io\excel\_base.py", line 713, in __new__
    engine = config.get_option(f"io.excel.{ext}.writer", silent=True)
  File "C:\Users\user\Envs\django\lib\site-packages\pandas\_config\config.py", line 233, in __call__
    return self.__func__(*args, **kwds)
  File "C:\Users\user\Envs\django\lib\site-packages\pandas\_config\config.py", line 105, in _get_option
    key = _get_single_key(pat, silent)
  File "C:\Users\user\Envs\django\lib\site-packages\pandas\_config\config.py", line 91, in _get_single_key
    raise OptionError(f"No such keys(s): {repr(pat)}")
pandas._config.config.OptionError: "No such keys(s): 'io.excel.xsx.writer'"

The above exception was the direct cause of the following exception:

Traceback (most recent call last):
  File "G:\AdventsProduct\Others\Medical Insurance\func.py", line 102, in get_write_file
    data_frame.to_excel(write_path, index=False)
  File "C:\Users\user\Envs\django\lib\site-packages\pandas\core\generic.py", line 2188, in to_excel
    formatter.write(
  File "C:\Users\user\Envs\django\lib\site-packages\pandas\io\formats\excel.py", line 815, in write
    writer = ExcelWriter(  # type: ignore[abstract]
  File "C:\Users\user\Envs\django\lib\site-packages\pandas\io\excel\_base.py", line 717, in __new__
    raise ValueError(f"No engine for filetype: '{ext}'") from err
ValueError: No engine for filetype: 'xsx'
