08-10-2022 12:23:07 PM Error in Get Read Proper Data Function!!!
Traceback (most recent call last):
  File "G:\AdventsProduct\Others\Medical Insurance\func.py", line 69, in get_read_proper_data
    data = pd.read_excel(file_location)
  File "C:\Users\user\Envs\django\lib\site-packages\pandas\util\_decorators.py", line 299, in wrapper
    return func(*args, **kwargs)
  File "C:\Users\user\Envs\django\lib\site-packages\pandas\io\excel\_base.py", line 336, in read_excel
    io = ExcelFile(io, storage_options=storage_options, engine=engine)
  File "C:\Users\user\Envs\django\lib\site-packages\pandas\io\excel\_base.py", line 1071, in __init__
    ext = inspect_excel_format(
  File "C:\Users\user\Envs\django\lib\site-packages\pandas\io\excel\_base.py", line 947, in inspect_excel_format
    assert content_or_path is not None
AssertionError
08-10-2022 12:23:07 PM Error in Get Filter Insurance Company Function!!!
Traceback (most recent call last):
  File "G:\AdventsProduct\Others\Medical Insurance\merge_data.py", line 47, in get_filter_insurance_company
    data_insurance_company = associate_merged_sales_merged_mis_data[associate_merged_sales_merged_mis_data['Insurance Company'] == insurance_company_name]
TypeError: string indices must be integers
08-10-2022 02:13:06 PM Error in Add Column with Date Val Function!!!
Traceback (most recent call last):
  File "C:\Users\user\Envs\django\lib\site-packages\pandas\core\indexes\base.py", line 3080, in get_loc
    return self._engine.get_loc(casted_key)
  File "pandas\_libs\index.pyx", line 70, in pandas._libs.index.IndexEngine.get_loc
  File "pandas\_libs\index.pyx", line 101, in pandas._libs.index.IndexEngine.get_loc
  File "pandas\_libs\hashtable_class_helper.pxi", line 4554, in pandas._libs.hashtable.PyObjectHashTable.get_item
  File "pandas\_libs\hashtable_class_helper.pxi", line 4562, in pandas._libs.hashtable.PyObjectHashTable.get_item
KeyError: 'exit_actual_dol'

The above exception was the direct cause of the following exception:

Traceback (most recent call last):
  File "G:\AdventsProduct\Others\Medical Insurance\func.py", line 126, in add_column_with_date_val
    data_frame[new_column_name] = data_frame[column].apply(
  File "C:\Users\user\Envs\django\lib\site-packages\pandas\core\frame.py", line 3024, in __getitem__
    indexer = self.columns.get_loc(key)
  File "C:\Users\user\Envs\django\lib\site-packages\pandas\core\indexes\base.py", line 3082, in get_loc
    raise KeyError(key) from err
KeyError: 'exit_actual_dol'
08-10-2022 02:13:07 PM Error in Get Write File Function!!!
Traceback (most recent call last):
  File "G:\AdventsProduct\Others\Medical Insurance\func.py", line 102, in get_write_file
    data_frame.to_excel(write_path, index=False)
AttributeError: 'NoneType' object has no attribute 'to_excel'
08-10-2022 05:50:38 PM Error in Medical Insurance Deletion Function!!!
Traceback (most recent call last):
  File "G:\AdventsProduct\Others\Medical Insurance\process.py", line 85, in medical_insurance_deletion
    data_deletion = classification.deletion(data_frame=data, inception_data_frame=inception_data)
TypeError: deletion() missing 2 required positional arguments: 'upload_month' and 'upload_year'
08-10-2022 05:50:38 PM Error in Get Read Proper Data Function!!!
Traceback (most recent call last):
  File "G:\AdventsProduct\Others\Medical Insurance\func.py", line 69, in get_read_proper_data
    data = pd.read_excel(file_location)
  File "C:\Users\user\Envs\django\lib\site-packages\pandas\util\_decorators.py", line 299, in wrapper
    return func(*args, **kwargs)
  File "C:\Users\user\Envs\django\lib\site-packages\pandas\io\excel\_base.py", line 336, in read_excel
    io = ExcelFile(io, storage_options=storage_options, engine=engine)
  File "C:\Users\user\Envs\django\lib\site-packages\pandas\io\excel\_base.py", line 1071, in __init__
    ext = inspect_excel_format(
  File "C:\Users\user\Envs\django\lib\site-packages\pandas\io\excel\_base.py", line 949, in inspect_excel_format
    with get_handle(
  File "C:\Users\user\Envs\django\lib\site-packages\pandas\io\common.py", line 651, in get_handle
    handle = open(handle, ioargs.mode)
FileNotFoundError: [Errno 2] No such file or directory: 'H:/Testing/Medical Insurance/A-Testing/Medical Insurance/august-2022/08102022/med_ins_aug_22_data_deletion.xlsx'
08-10-2022 05:51:34 PM Error in Addition and Deletion Function!!!
Traceback (most recent call last):
  File "G:\AdventsProduct\Others\Medical Insurance\classifications.py", line 201, in addition_and_deletion
    data_frame['classification_1'] = data_frame.apply(
AttributeError: 'str' object has no attribute 'apply'
08-10-2022 05:51:34 PM Error in Get Write File Function!!!
Traceback (most recent call last):
  File "G:\AdventsProduct\Others\Medical Insurance\func.py", line 102, in get_write_file
    data_frame.to_excel(write_path, index=False)
AttributeError: 'str' object has no attribute 'to_excel'
08-10-2022 05:51:34 PM Error in Get Read Proper Data Function!!!
Traceback (most recent call last):
  File "G:\AdventsProduct\Others\Medical Insurance\func.py", line 69, in get_read_proper_data
    data = pd.read_excel(file_location)
  File "C:\Users\user\Envs\django\lib\site-packages\pandas\util\_decorators.py", line 299, in wrapper
    return func(*args, **kwargs)
  File "C:\Users\user\Envs\django\lib\site-packages\pandas\io\excel\_base.py", line 336, in read_excel
    io = ExcelFile(io, storage_options=storage_options, engine=engine)
  File "C:\Users\user\Envs\django\lib\site-packages\pandas\io\excel\_base.py", line 1071, in __init__
    ext = inspect_excel_format(
  File "C:\Users\user\Envs\django\lib\site-packages\pandas\io\excel\_base.py", line 949, in inspect_excel_format
    with get_handle(
  File "C:\Users\user\Envs\django\lib\site-packages\pandas\io\common.py", line 651, in get_handle
    handle = open(handle, ioargs.mode)
FileNotFoundError: [Errno 2] No such file or directory: 'H:/Testing/Medical Insurance/A-Testing/Medical Insurance/august-2022/08102022/med_ins_aug_22_data_addition_and_deletion.xlsx'
08-10-2022 05:52:31 PM Error in Already Deletion Function!!!
Traceback (most recent call last):
  File "G:\AdventsProduct\Others\Medical Insurance\classifications.py", line 243, in already_deletion
    data_frame['classification_1'] = data_frame.apply(
AttributeError: 'str' object has no attribute 'apply'
08-10-2022 05:52:31 PM Error in Get Write File Function!!!
Traceback (most recent call last):
  File "G:\AdventsProduct\Others\Medical Insurance\func.py", line 102, in get_write_file
    data_frame.to_excel(write_path, index=False)
AttributeError: 'str' object has no attribute 'to_excel'
08-10-2022 05:52:31 PM Error in Get Read Proper Data Function!!!
Traceback (most recent call last):
  File "G:\AdventsProduct\Others\Medical Insurance\func.py", line 69, in get_read_proper_data
    data = pd.read_excel(file_location)
  File "C:\Users\user\Envs\django\lib\site-packages\pandas\util\_decorators.py", line 299, in wrapper
    return func(*args, **kwargs)
  File "C:\Users\user\Envs\django\lib\site-packages\pandas\io\excel\_base.py", line 336, in read_excel
    io = ExcelFile(io, storage_options=storage_options, engine=engine)
  File "C:\Users\user\Envs\django\lib\site-packages\pandas\io\excel\_base.py", line 1071, in __init__
    ext = inspect_excel_format(
  File "C:\Users\user\Envs\django\lib\site-packages\pandas\io\excel\_base.py", line 949, in inspect_excel_format
    with get_handle(
  File "C:\Users\user\Envs\django\lib\site-packages\pandas\io\common.py", line 651, in get_handle
    handle = open(handle, ioargs.mode)
FileNotFoundError: [Errno 2] No such file or directory: 'H:/Testing/Medical Insurance/A-Testing/Medical Insurance/august-2022/08102022/med_ins_aug_22_data_already_deletion.xlsx'
08-10-2022 05:53:19 PM Error in Addition Function!!!
Traceback (most recent call last):
  File "G:\AdventsProduct\Others\Medical Insurance\classifications.py", line 271, in additions
    data_frame['classification_1'] = data_frame.apply(
AttributeError: 'str' object has no attribute 'apply'
08-10-2022 05:53:19 PM Error in Get Write File Function!!!
Traceback (most recent call last):
  File "G:\AdventsProduct\Others\Medical Insurance\func.py", line 102, in get_write_file
    data_frame.to_excel(write_path, index=False)
AttributeError: 'str' object has no attribute 'to_excel'
08-10-2022 05:53:19 PM Error in Get Read Proper Data Function!!!
Traceback (most recent call last):
  File "G:\AdventsProduct\Others\Medical Insurance\func.py", line 69, in get_read_proper_data
    data = pd.read_excel(file_location)
  File "C:\Users\user\Envs\django\lib\site-packages\pandas\util\_decorators.py", line 299, in wrapper
    return func(*args, **kwargs)
  File "C:\Users\user\Envs\django\lib\site-packages\pandas\io\excel\_base.py", line 336, in read_excel
    io = ExcelFile(io, storage_options=storage_options, engine=engine)
  File "C:\Users\user\Envs\django\lib\site-packages\pandas\io\excel\_base.py", line 1071, in __init__
    ext = inspect_excel_format(
  File "C:\Users\user\Envs\django\lib\site-packages\pandas\io\excel\_base.py", line 949, in inspect_excel_format
    with get_handle(
  File "C:\Users\user\Envs\django\lib\site-packages\pandas\io\common.py", line 651, in get_handle
    handle = open(handle, ioargs.mode)
FileNotFoundError: [Errno 2] No such file or directory: 'H:/Testing/Medical Insurance/A-Testing/Medical Insurance/august-2022/08102022/med_ins_aug_22_data_addition.xlsx'
08-10-2022 05:54:15 PM Error in Reactivation Function!!!
Traceback (most recent call last):
  File "G:\AdventsProduct\Others\Medical Insurance\classifications.py", line 310, in reactivation
    data_frame['classification_1'] = data_frame.apply(
AttributeError: 'str' object has no attribute 'apply'
08-10-2022 05:54:15 PM Error in Get Write File Function!!!
Traceback (most recent call last):
  File "G:\AdventsProduct\Others\Medical Insurance\func.py", line 102, in get_write_file
    data_frame.to_excel(write_path, index=False)
AttributeError: 'str' object has no attribute 'to_excel'
08-10-2022 05:54:15 PM Error in Get Read Proper Data Function!!!
Traceback (most recent call last):
  File "G:\AdventsProduct\Others\Medical Insurance\func.py", line 69, in get_read_proper_data
    data = pd.read_excel(file_location)
  File "C:\Users\user\Envs\django\lib\site-packages\pandas\util\_decorators.py", line 299, in wrapper
    return func(*args, **kwargs)
  File "C:\Users\user\Envs\django\lib\site-packages\pandas\io\excel\_base.py", line 336, in read_excel
    io = ExcelFile(io, storage_options=storage_options, engine=engine)
  File "C:\Users\user\Envs\django\lib\site-packages\pandas\io\excel\_base.py", line 1071, in __init__
    ext = inspect_excel_format(
  File "C:\Users\user\Envs\django\lib\site-packages\pandas\io\excel\_base.py", line 949, in inspect_excel_format
    with get_handle(
  File "C:\Users\user\Envs\django\lib\site-packages\pandas\io\common.py", line 651, in get_handle
    handle = open(handle, ioargs.mode)
FileNotFoundError: [Errno 2] No such file or directory: 'H:/Testing/Medical Insurance/A-Testing/Medical Insurance/august-2022/08102022/med_ins_aug_22_data_reactivation.xlsx'
08-10-2022 05:54:15 PM Error in Next Month Addition Function!!!
Traceback (most recent call last):
  File "G:\AdventsProduct\Others\Medical Insurance\classifications.py", line 339, in next_month_addition
    data_frame['classification_1'] = data_frame.apply(
AttributeError: 'str' object has no attribute 'apply'
08-10-2022 05:54:15 PM Error in Get Write File Function!!!
Traceback (most recent call last):
  File "G:\AdventsProduct\Others\Medical Insurance\func.py", line 102, in get_write_file
    data_frame.to_excel(write_path, index=False)
AttributeError: 'str' object has no attribute 'to_excel'
08-10-2022 05:54:15 PM Error in Get Read Proper Data Function!!!
Traceback (most recent call last):
  File "G:\AdventsProduct\Others\Medical Insurance\func.py", line 69, in get_read_proper_data
    data = pd.read_excel(file_location)
  File "C:\Users\user\Envs\django\lib\site-packages\pandas\util\_decorators.py", line 299, in wrapper
    return func(*args, **kwargs)
  File "C:\Users\user\Envs\django\lib\site-packages\pandas\io\excel\_base.py", line 336, in read_excel
    io = ExcelFile(io, storage_options=storage_options, engine=engine)
  File "C:\Users\user\Envs\django\lib\site-packages\pandas\io\excel\_base.py", line 1071, in __init__
    ext = inspect_excel_format(
  File "C:\Users\user\Envs\django\lib\site-packages\pandas\io\excel\_base.py", line 949, in inspect_excel_format
    with get_handle(
  File "C:\Users\user\Envs\django\lib\site-packages\pandas\io\common.py", line 651, in get_handle
    handle = open(handle, ioargs.mode)
FileNotFoundError: [Errno 2] No such file or directory: 'H:/Testing/Medical Insurance/A-Testing/Medical Insurance/august-2022/08102022/med_ins_aug_22_data_next_month_addition.xlsx'
08-10-2022 05:55:12 PM Error in Next Month Deletion Function!!!
Traceback (most recent call last):
  File "G:\AdventsProduct\Others\Medical Insurance\classifications.py", line 380, in next_month_deletion
    data_frame['classification_1'] = data_frame.apply(
AttributeError: 'str' object has no attribute 'apply'
08-10-2022 05:55:12 PM Error in Get Write File Function!!!
Traceback (most recent call last):
  File "G:\AdventsProduct\Others\Medical Insurance\func.py", line 102, in get_write_file
    data_frame.to_excel(write_path, index=False)
AttributeError: 'str' object has no attribute 'to_excel'
10-10-2022 08:55:27 AM Error in Get Read Proper Data Function!!!
Traceback (most recent call last):
  File "G:\AdventsProduct\Others\Medical Insurance\func.py", line 69, in get_read_proper_data
    data = pd.read_excel(file_location)
  File "C:\Users\user\Envs\django\lib\site-packages\pandas\util\_decorators.py", line 299, in wrapper
    return func(*args, **kwargs)
  File "C:\Users\user\Envs\django\lib\site-packages\pandas\io\excel\_base.py", line 336, in read_excel
    io = ExcelFile(io, storage_options=storage_options, engine=engine)
  File "C:\Users\user\Envs\django\lib\site-packages\pandas\io\excel\_base.py", line 1071, in __init__
    ext = inspect_excel_format(
  File "C:\Users\user\Envs\django\lib\site-packages\pandas\io\excel\_base.py", line 949, in inspect_excel_format
    with get_handle(
  File "C:\Users\user\Envs\django\lib\site-packages\pandas\io\common.py", line 651, in get_handle
    handle = open(handle, ioargs.mode)
FileNotFoundError: [Errno 2] No such file or directory: 'H:/Testing/Medical Insurance/A-Testing/Medical Insurance/august-2022/08102022/med_ins_aug_22_data_ptp.xlsx'
